TTLocalizer: Running in language: english
from toontown.toonbase.TTLocalizerEnglish import *
OTPLocalizer: Running in language: english
from otp.otpbase.OTPLocalizerEnglish import *
Preloading suits...
Preloading Toon heads...
Preloading avatars...
{401000001: <toontown.distributed.ToontownDistrict.ToontownDistrict instance at 0x1E5341C0>}
__handleAvatarChooserDone: 100000003, 'Little Zippy', ('rsl', 'ls', 'l', 'm', 19, 0, 19, 19, 10, 9, 0, 9, 7, 0), 1
0
Reading DNA file... phase_4/dna/storage.pdna
Reading DNA file... phase_3.5/dna/storage_interior.pdna
Reading DNA file... phase_4/dna/storage_TT.pdna
Reading DNA file... phase_4/dna/storage_TT_sz.pdna
Reading DNA file... phase_4/dna/toontown_central_sz.pdna
Exception occurred while processing Func-TTC-40 of Sequence-124:
Sequence-124:
  0.000 Sequence-124 {
  0.000   *Func-TTC-40
  0.000   Wait dur 0.5
  0.500   *Func-DG-41
  0.500   Wait dur 0.5
  1.000   *Func-MML-42
  1.000   Wait dur 0.5
  1.500   *Func-TB-43
  1.500   Wait dur 0.5
  2.000   *Func-DDL-44
  2.000   *Func-displayWhisper-45
  2.000 }

Traceback (most recent call last):
  File "D:\Documents\ToontownSourcecode\Panda3D-1.9.0\direct\showbase\ShowBase.py", line 1801, in __ivalLoop
    IntervalManager.ivalMgr.step()
  File "D:\Documents\ToontownSourcecode\Panda3D-1.9.0\direct\interval\IntervalManager.py", line 96, in step
    self.__doPythonCallbacks()
  File "D:\Documents\ToontownSourcecode\Panda3D-1.9.0\direct\interval\IntervalManager.py", line 124, in __doPythonCallbacks
    self.ivals[index].privPostEvent()
  File "D:\Documents\ToontownSourcecode\Panda3D-1.9.0\direct\interval\MetaInterval.py", line 518, in privPostEvent
    self.__doPythonCallbacks()
  File "D:\Documents\ToontownSourcecode\Panda3D-1.9.0\direct\interval\MetaInterval.py", line 494, in __doPythonCallbacks
    ival.privDoEvent(t, eventType)
  File "D:\Documents\ToontownSourcecode\Panda3D-1.9.0\direct\interval\Interval.py", line 207, in privDoEvent
    self.privInstant()
  File "D:\Documents\ToontownSourcecode\Panda3D-1.9.0\direct\interval\FunctionInterval.py", line 88, in privInstant
    self.function(*self.extraArgs, **self.kw)
  File "<string>", line 173, in TTC
  File "D:\Documents\ToontownSourcecode\Panda3D-1.9.0\direct\distributed\DoInterestManager.py", line 190, in addInterest
    self._sendAddInterest(handle, contextId, parentId, zoneIdList, description)
  File "D:\Documents\ToontownSourcecode\Panda3D-1.9.0\direct\distributed\DoInterestManager.py", line 501, in _sendAddInterest
    action, description, handle, contextId, parentId, zoneIdList)
  File "D:\Documents\ToontownSourcecode\Panda3D-1.9.0\direct\distributed\DoInterestManager.py", line 446, in _addDebugInterestHistory
    DoInterestManager._debug_maxDescriptionLen, len(description))
TypeError: object of type 'int' has no len()
Traceback (most recent call last):
  File "otp\otpbase\OTPBase.py", line 236, in run
    taskMgr.run()
  File "D:\Documents\ToontownSourcecode\Panda3D-1.9.0\direct\task\Task.py", line 502, in run
    self.step()
  File "D:\Documents\ToontownSourcecode\Panda3D-1.9.0\direct\task\Task.py", line 460, in step
    self.mgr.poll()
  File "D:\Documents\ToontownSourcecode\Panda3D-1.9.0\direct\showbase\ShowBase.py", line 1801, in __ivalLoop
    IntervalManager.ivalMgr.step()
  File "D:\Documents\ToontownSourcecode\Panda3D-1.9.0\direct\interval\IntervalManager.py", line 96, in step
    self.__doPythonCallbacks()
  File "D:\Documents\ToontownSourcecode\Panda3D-1.9.0\direct\interval\IntervalManager.py", line 124, in __doPythonCallbacks
    self.ivals[index].privPostEvent()
  File "D:\Documents\ToontownSourcecode\Panda3D-1.9.0\direct\interval\MetaInterval.py", line 518, in privPostEvent
    self.__doPythonCallbacks()
  File "D:\Documents\ToontownSourcecode\Panda3D-1.9.0\direct\interval\MetaInterval.py", line 494, in __doPythonCallbacks
    ival.privDoEvent(t, eventType)
  File "D:\Documents\ToontownSourcecode\Panda3D-1.9.0\direct\interval\Interval.py", line 207, in privDoEvent
    self.privInstant()
  File "D:\Documents\ToontownSourcecode\Panda3D-1.9.0\direct\interval\FunctionInterval.py", line 88, in privInstant
    self.function(*self.extraArgs, **self.kw)
  File "<string>", line 173, in TTC
  File "D:\Documents\ToontownSourcecode\Panda3D-1.9.0\direct\distributed\DoInterestManager.py", line 190, in addInterest
    self._sendAddInterest(handle, contextId, parentId, zoneIdList, description)
  File "D:\Documents\ToontownSourcecode\Panda3D-1.9.0\direct\distributed\DoInterestManager.py", line 501, in _sendAddInterest
    action, description, handle, contextId, parentId, zoneIdList)
  File "D:\Documents\ToontownSourcecode\Panda3D-1.9.0\direct\distributed\DoInterestManager.py", line 446, in _addDebugInterestHistory
    DoInterestManager._debug_maxDescriptionLen, len(description))
TypeError: object of type 'int' has no len()
